Workbook

Sheet Легенда
B2: Управление событиями ГЭС-2 — рабочий шаблон
B3: Реестр событий + треки жизненного цикла + RACI + дашборд статусов. Данные на 09.08.2026.
B5: Как устроен файл
B6: Реестр событий | C6: Главный лист. Одна строка = одно событие. Здесь заполняются карточка события и статусы отделов.
B7: Этапы по трекам | C7: Справочник: какие этапы проходит событие в зависимости от трека сложности и в какие сроки (T-минус дней до события).
B8: RACI | C8: Кто Ответственный / кто Согласует / с кем Консультируются / кого Информируют — по каждому этапу, отдельно для каждого трека.
B9: Дашборд | C9: Автосводка по всем событиям реестра: сколько событий в каком статусе, по трекам, у кого больше всего 'красных' зон.
B11: Что редактировать
B12: • | C12: Жёлтая заливка = ячейки, которые нужно заполнять/проверять вручную. 'T-минус' и 'Общий статус' считаются формулой и не редактируются.
B13: • | C13: В 'Реестре событий' выбор значений — через выпадающие списки (Категория, Трек, Текущий этап, все статусные столбцы).
B14: • | C14: Реестр заполнен 72 событиями из calendar2026.xlsx (данные сайта ges-2.org на 09.08.2026, до конца 2026 года). Категория определена автоматически по подтипу события (справочник ges2-categorii-sobytiy.md), Трек — по категории + признаку 'Платно' + ключевым словам (например, 'Саундсистем').
B15: • | C15: Столбцы 'Продюсер' и все статусы по отделам (Продакшн…Охрана) — пустые: календарь с сайта не содержит эту информацию, её нужно проставить вручную по мере включения события в операционную работу.
B16: • | C16: 'Текущий этап' — авто-расчёт по датам события и T-минус срокам трека (см. 'Этапы по трекам'): это стартовая подсказка, не подтверждённый факт готовности — сверьте с реальным состоянием подготовки.
B17: • | C17: Сроки (T-минус) в листе 'Этапы по трекам' и состав RACI — заданы как рабочая гипотеза по умолчанию. Их нужно свериться и поправить под реальные регламенты отделов — это не факты ГЭС-2, а предлагаемая стартовая логика.
B19: Цветовой код статусов (столбцы I:N и 'Общий статус' в Реестре)
B20: Зелёный | C20: Этап идёт по плану
B21: Жёлтый | C21: Есть риск срыва срока/нужна помощь
B22: Красный | C22: Срыв срока / блокер, нужна эскалация
B23: Не начат | C23: Этап ещё не наступил по плану
B24: Н/Д | C24: Отдел не участвует в этом событии
B26: Треки сложности (зачем они)
B27: Лёгкий / Средний / Тяжёлый | C27: При ~2000 событий/год гнать всё через один тяжёлый процесс нецелесообразно. Трек задаёт, какие этапы и отделы обязательны — см. 'Этапы по трекам' и 'RACI'.

Sheet Реестр событий
A1: ID | B1: Название события | C1: Категория | D1: Трек | E1: Дата начала | F1: Дата окончания | G1: T-минус (дней) | H1: Продюсер | I1: Текущий этап | J1: Продакшн/техника | K1: Маркетинг | L1: PR | M1: Площадка | N1: Питание | O1: Охрана | P1: Общий статус | Q1: Платно | R1: Риски / комментарий | S1: Ссылка
A2: 1 | B2: Курс подготовки глухих музейных специалистов | C2: Лекция | D2: Лёгкий | E2: 45931 | F2: 46265 | G2: =E2-TODAY() | I2: Проведение | P2: =IF(COUNTBLANK(J2:O2)=6,"",IF(COUNTIF(J2:O2,"Красный")>0,"Красный",IF(COUNTIF(J2:O2,"Жёлтый")>0,"Жёлтый",IF(COUNTIF(J2:O2,"Не начат")>0,"Не начат","Зелёный")))) | Q2: Нет | S2: https://ges-2.org/training-course-for-deaf-museum-professionals
A3: 2 | B3: Хадзар мечты | C3: Медиаторский тур | D3: Лёгкий | E3: 46135 | F3: 46278 | G3: =E3-TODAY() | I3: Проведение | P3: =IF(COUNTBLANK(J3:O3)=6,"",IF(COUNTIF(J3:O3,"Красный")>0,"Красный",IF(COUNTIF(J3:O3,"Жёлтый")>0,"Жёлтый",IF(COUNTIF(J3:O3,"Не начат")>0,"Не начат","Зелёный")))) | Q3: Нет | R3: Выставка закрывается 13.09 — почти одновременно с «Москва — Ханой» (20.09). | S3: https://ges-2.org/khadzar-of-dreams-mediated-tour
A4: 3 | B4: Хадзар мечты | C4: Выставка | D4: Тяжёлый | E4: 46135 | F4: 46278 | G4: =E4-TODAY() | I4: Проведение | P4: =IF(COUNTBLANK(J4:O4)=6,"",IF(COUNTIF(J4:O4,"Красный")>0,"Красный",IF(COUNTIF(J4:O4,"Жёлтый")>0,"Жёлтый",IF(COUNTIF(J4:O4,"Не начат")>0,"Не начат","Зелёный")))) | Q4: Нет | R4: Выставка закрывается 13.09 — почти одновременно с «Москва — Ханой» (20.09). | S4: https://ges-2.org/projects/khadzar-of-dreams
A5: 4 | B5: Лес, полный красот и чудес | C5: Прочее | D5: Лёгкий | E5: 46151 | F5: 46263 | G5: =E5-TODAY() | I5: Проведение | P5: =IF(COUNTBLANK(J5:O5)=6,"",IF(COUNTIF(J5:O5,"Красный")>0,"Красный",IF(COUNTIF(J5:O5,"Жёлтый")>0,"Жёлтый",IF(COUNTIF(J5:O5,"Не начат")>0,"Не начат","Зелёный")))) | Q5: Нет | S5: https://ges-2.org/forest-full-of-beauty-and-wonders
A6: 5 | B6: Москва — Ханой. Ландшафты оптимизма | C6: Выставка | D6: Тяжёлый | E6: 46163 | F6: 46285 | G6: =E6-TODAY() | I6: Проведение | P6: =IF(COUNTBLANK(J6:O6)=6,"",IF(COUNTIF(J6:O6,"Красный")>0,"Красный",IF(COUNTIF(J6:O6,"Жёлтый")>0,"Жёлтый",IF(COUNTIF(J6:O6,"Не начат")>0,"Не начат","Зелёный")))) | Q6: Нет | R6: Закрытие 20.09 — окно на монтаж следующей выставки («Натюрморт…», открытие 15.10) около месяца. | S6: https://ges-2.org/projects/moscow-hanoi-landscapes-of-optimism
A7: 6 | B7: Москва — Ханой. Ландшафты оптимизма | C7: Медиаторский тур | D7: Лёгкий | E7: 46163 | F7: 46285 | G7: =E7-TODAY() | I7: Проведение | P7: =IF(COUNTBLANK(J7:O7)=6,"",IF(COUNTIF(J7:O7,"Красный")>0,"Красный",IF(COUNTIF(J7:O7,"Жёлтый")>0,"Жёлтый",IF(COUNTIF(J7:O7,"Не начат")>0,"Не начат","Зелёный")))) | Q7: Нет | R7: Закрытие 20.09 — окно на монтаж следующей выставки («Натюрморт…», открытие 15.10) около месяца. | S7: https://ges-2.org/moscow-hanoi-landscapes-of-optimism-mediated-tour
A8: 7 | B8: Игры на лужайке | C8: Прочее | D8: Лёгкий | E8: 46172 | F8: 46296 | G8: =E8-TODAY() | I8: Проведение | P8: =IF(COUNTBLANK(J8:O8)=6,"",IF(COUNTIF(J8:O8,"Красный")>0,"Красный",IF(COUNTIF(J8:O8,"Жёлтый")>0,"Жёлтый",IF(COUNTIF(J8:O8,"Не начат")>0,"Не начат","Зелёный")))) | Q8: Нет | S8: https://ges-2.org/lawn-games
A9: 8 | B9: Фотооснова. Лаборатория печатных практик для художников | C9: Прочее | D9: Лёгкий | E9: 46174 | F9: 46325 | G9: =E9-TODAY() | I9: Проведение | P9: =IF(COUNTBLANK(J9:O9)=6,"",IF(COUNTIF(J9:O9,"Красный")>0,"Красный",IF(COUNTIF(J9:O9,"Жёлтый")>0,"Жёлтый",IF(COUNTIF(J9:O9,"Не начат")>0,"Не начат","Зелёный")))) | Q9: Нет | S9: https://ges-2.org/photo-basis-printmaking-practices-lab-for-artists
A10: 9 | B10: Как тебе тут? | C10: Прочее | D10: Лёгкий | E10: 46175 | F10: 46285 | G10: =E10-TODAY() | I10: Проведение | P10: =IF(COUNTBLANK(J10:O10)=6,"",IF(COUNTIF(J10:O10,"Красный")>0,"Красный",IF(COUNTIF(J10:O10,"Жёлтый")>0,"Жёлтый",IF(COUNTIF(J10:O10,"Не начат")>0,"Не начат","Зелёный")))) | Q10: Нет | S10: https://ges-2.org/how-do-you-like-it-here
A11: 10 | B11: Весь мир здесь обретает дом: по следам Тагора | C11: Выставка | D11: Тяжёлый | E11: 46198 | F11: 46257 | G11: =E11-TODAY() | I11: Проведение | P11: =IF(COUNTBLANK(J11:O11)=6,"",IF(COUNTIF(J11:O11,"Красный")>0,"Красный",IF(COUNTIF(J11:O11,"Жёлтый")>0,"Жёлтый",IF(COUNTIF(J11:O11,"Не начат")>0,"Не начат","Зелёный")))) | Q11: Нет | R11: Закрытие 23.08 — одна из трёх почти одновременно закрывающихся выставок. | S11: https://ges-2.org/projects/the-world-in-a-single-nest-following-the-way-of-tagore
A12: 11 | B12: В тени баньяна | C12: Прочее | D12: Лёгкий | E12: 46198 | F12: 46257 | G12: =E12-TODAY() | I12: Проведение | P12: =IF(COUNTBLANK(J12:O12)=6,"",IF(COUNTIF(J12:O12,"Красный")>0,"Красный",IF(COUNTIF(J12:O12,"Жёлтый")>0,"Жёлтый",IF(COUNTIF(J12:O12,"Не начат")>0,"Не начат","Зелёный")))) | Q12: Нет | S12: https://ges-2.org/in-the-shade-of-the-banyan-tree
A13: 12 | B13: Весь мир здесь обретает дом: по следам Тагора | C13: Медиаторский тур | D13: Лёгкий | E13: 46198 | F13: 46257 | G13: =E13-TODAY() | I13: Проведение | P13: =IF(COUNTBLANK(J13:O13)=6,"",IF(COUNTIF(J13:O13,"Красный")>0,"Красный",IF(COUNTIF(J13:O13,"Жёлтый")>0,"Жёлтый",IF(COUNTIF(J13:O13,"Не начат")>0,"Не начат","Зелёный")))) | Q13: Нет | R13: Закрытие 23.08 — одна из трёх почти одновременно закрывающихся выставок. | S13: https://ges-2.org/the-world-in-a-single-nest-following-the-way-of-tagore-mediated-tour
A14: 13 | B14: Роща чувств. Новое звучание | C14: Танцевальный показ | D14: Средний | E14: 46201 | F14: 46264 | G14: =E14-TODAY() | I14: Проведение | P14: =IF(COUNTBLANK(J14:O14)=6,"",IF(COUNTIF(J14:O14,"Красный")>0,"Красный",IF(COUNTIF(J14:O14,"Жёлтый")>0,"Жёлтый",IF(COUNTIF(J14:O14,"Не начат")>0,"Не начат","Зелёный")))) | Q14: Нет | S14: https://ges-2.org/forest-of-feelings-the-new-sound
A15: 14 | B15: Палисадник-2026 | C15: Выставка | D15: Тяжёлый | E15: 46204 | F15: 46295 | G15: =E15-TODAY() | I15: Проведение | P15: =IF(COUNTBLANK(J15:O15)=6,"",IF(COUNTIF(J15:O15,"Красный")>0,"Красный",IF(COUNTIF(J15:O15,"Жёлтый")>0,"Жёлтый",IF(COUNTIF(J15:O15,"Не начат")>0,"Не начат","Зелёный")))) | Q15: Нет | S15: https://ges-2.org/projects/front-garden-2026
A16: 15 | B16: Как стать меньше мухи | C16: Прочее | D16: Лёгкий | E16: 46205 | F16: 46254 | G16: =E16-TODAY() | I16: Проведение | P16: =IF(COUNTBLANK(J16:O16)=6,"",IF(COUNTIF(J16:O16,"Красный")>0,"Красный",IF(COUNTIF(J16:O16,"Жёлтый")>0,"Жёлтый",IF(COUNTIF(J16:O16,"Не начат")>0,"Не начат","Зелёный")))) | Q16: Нет | S16: https://ges-2.org/how-to-become-smaller-than-a-fly
A17: 16 | B17: Вне стен: прогулка по Музеону | C17: Медиаторский тур | D17: Лёгкий | E17: 46210 | F17: 46293 | G17: =E17-TODAY() | I17: Проведение | P17: =IF(COUNTBLANK(J17:O17)=6,"",IF(COUNTIF(J17:O17,"Красный")>0,"Красный",IF(COUNTIF(J17:O17,"Жёлтый")>0,"Жёлтый",IF(COUNTIF(J17:O17,"Не начат")>0,"Не начат","Зелёный")))) | Q17: Нет | S17: https://ges-2.org/outside-the-walls-a-walk-in-muzeon-park
A18: 17 | B18: К сердцу земли. Учиться у природы | C18: Медиаторский тур | D18: Лёгкий | E18: 46215 | F18: 46257 | G18: =E18-TODAY() | I18: Проведение | P18: =IF(COUNTBLANK(J18:O18)=6,"",IF(COUNTIF(J18:O18,"Красный")>0,"Красный",IF(COUNTIF(J18:O18,"Жёлтый")>0,"Жёлтый",IF(COUNTIF(J18:O18,"Не начат")>0,"Не начат","Зелёный")))) | Q18: Нет | S18: https://ges-2.org/to-the-heart-of-the-earth-learning-from-nature
A19: 18 | B19: Программа для живописцев и скульпторов. Открытый набор на второй сезон | C19: Прочее | D19: Лёгкий | E19: 46216 | F19: 46265 | G19: =E19-TODAY() | I19: Проведение | P19: =IF(COUNTBLANK(J19:O19)=6,"",IF(COUNTIF(J19:O19,"Красный")>0,"Красный",IF(COUNTIF(J19:O19,"Жёлтый")>0,"Жёлтый",IF(COUNTIF(J19:O19,"Не начат")>0,"Не начат","Зелёный")))) | Q19: Нет | S19: https://ges-2.org/programme-for-painters-and-sculptors-open-call-for-season-2
A20: 19 | B20: Йога в Роще | C20: Медиаторский тур | D20: Лёгкий | E20: 46221 | F20: 46260 | G20: =E20-TODAY() | I20: Проведение | P20: =IF(COUNTBLANK(J20:O20)=6,"",IF(COUNTIF(J20:O20,"Красный")>0,"Красный",IF(COUNTIF(J20:O20,"Жёлтый")>0,"Жёлтый",IF(COUNTIF(J20:O20,"Не начат")>0,"Не начат","Зелёный")))) | Q20: Нет | S20: https://ges-2.org/yoga-in-the-forest
A21: 20 | B21: За контурами моды. Летняя программа медиации | C21: Лекция | D21: Лёгкий | E21: 46229 | F21: 46260 | G21: =E21-TODAY() | I21: Проведение | P21: =IF(COUNTBLANK(J21:O21)=6,"",IF(COUNTIF(J21:O21,"Красный")>0,"Красный",IF(COUNTIF(J21:O21,"Жёлтый")>0,"Жёлтый",IF(COUNTIF(J21:O21,"Не начат")>0,"Не начат","Зелёный")))) | Q21: Нет | S21: https://ges-2.org/beyond-fashion-contours-mediation-summer-programme
A22: 21 | B22: Открытый факультет медиации. Владивосток/Калининград. Открытый набор | C22: Прочее | D22: Лёгкий | E22: 46232 | F22: 46245 | G22: =E22-TODAY() | I22: Проведение | P22: =IF(COUNTBLANK(J22:O22)=6,"",IF(COUNTIF(J22:O22,"Красный")>0,"Красный",IF(COUNTIF(J22:O22,"Жёлтый")>0,"Жёлтый",IF(COUNTIF(J22:O22,"Не начат")>0,"Не начат","Зелёный")))) | Q22: Нет | S22: https://ges-2.org/open-faculty-of-mediation-vladivostok-kaliningrad-open-call
A23: 22 | B23: След и ритм | C23: Прочее | D23: Лёгкий | E23: 46238 | F23: 46247 | G23: =E23-TODAY() | I23: Проведение | P23: =IF(COUNTBLANK(J23:O23)=6,"",IF(COUNTIF(J23:O23,"Красный")>0,"Красный",IF(COUNTIF(J23:O23,"Жёлтый")>0,"Жёлтый",IF(COUNTIF(J23:O23,"Не начат")>0,"Не начат","Зелёный")))) | Q23: Нет | S23: https://ges-2.org/trace-and-rhythm
A24: 23 | B24: Что с лицом? | C24: Кинопоказ | D24: Средний | E24: 46240 | F24: 46253 | G24: =E24-TODAY() | I24: Проведение | P24: =IF(COUNTBLANK(J24:O24)=6,"",IF(COUNTIF(J24:O24,"Красный")>0,"Красный",IF(COUNTIF(J24:O24,"Жёлтый")>0,"Жёлтый",IF(COUNTIF(J24:O24,"Не начат")>0,"Не начат","Зелёный")))) | Q24: Нет | S24: https://ges-2.org/projects/what-s-with-the-face
A25: 24 | B25: Другой Тагор: творческая вселенная от экспериментов в графике до музыкальной революции | C25: Лекция | D25: Лёгкий | E25: 46245 | F25: 46252 | G25: =E25-TODAY() | I25: Финальная неделя | P25: =IF(COUNTBLANK(J25:O25)=6,"",IF(COUNTIF(J25:O25,"Красный")>0,"Красный",IF(COUNTIF(J25:O25,"Жёлтый")>0,"Жёлтый",IF(COUNTIF(J25:O25,"Не начат")>0,"Не начат","Зелёный")))) | Q25: Нет | S25: https://ges-2.org/the-other-tagore-the-creative-universe
... A40: 39 | B40: Небывальщина | C40: Прочее | D40: Лёгкий | E40: 46257 | F40: 46264 | G40: =E40-TODAY() | I40: Маркетинг/PR-план | P40: =IF(COUNTBLANK(J40:O40)=6,"",IF(COUNTIF(J40:O40,"Красный")>0,"Красный",IF(COUNTIF(J40:O40,"Жёлтый")>0,"Жёлтый",IF(COUNTIF(J40:O40,"Не начат")>0,"Не начат","Зелёный")))) | Q40: Нет | S40: https://ges-2.org/imaginary-creatures
A41: 40 | B41: ГЭС-2 Саундсистем 4. Mind* | C41: Лекция | D41: Тяжёлый | E41: 46258 | F41: 46260 | G41: =E41-TODAY() | I41: Продакшн | P41: =IF(COUNTBLANK(J41:O41)=6,"",IF(COUNTIF(J41:O41,"Красный")>0,"Красный",IF(COUNTIF(J41:O41,"Жёлтый")>0,"Жёлтый",IF(COUNTIF(J41:O41,"Не начат")>0,"Не начат","Зелёный")))) | Q41: Нет | R41: Крупный музыкальный уикенд (24–30.08) — пиковая нагрузка на посетительский сервис и парковку. | S41: https://ges-2.org/ges-2-soundsystem-4-mind
A42: 41 | B42: ГЭС-2 Саундсистем 4 | C42: Лекция | D42: Тяжёлый | E42: 46258 | F42: 46264 | G42: =E42-TODAY() | I42: Продакшн | P42: =IF(COUNTBLANK(J42:O42)=6,"",IF(COUNTIF(J42:O42,"Красный")>0,"Красный",IF(COUNTIF(J42:O42,"Жёлтый")>0,"Жёлтый",IF(COUNTIF(J42:O42,"Не начат")>0,"Не начат","Зелёный")))) | Q42: Нет | R42: Крупный музыкальный уикенд (24–30.08) — пиковая нагрузка на посетительский сервис и парковку. | S42: https://ges-2.org/projects/ges-2-soundsystem-4
A43: 42 | B43: ГЭС-2 Саундсистем 4. Body* | C43: Лекция | D43: Тяжёлый | E43: 46258 | F43: 46264 | G43: =E43-TODAY() | I43: Продакшн | P43: =IF(COUNTBLANK(J43:O43)=6,"",IF(COUNTIF(J43:O43,"Красный")>0,"Красный",IF(COUNTIF(J43:O43,"Жёлтый")>0,"Жёлтый",IF(COUNTIF(J43:O43,"Не начат")>0,"Не начат","Зелёный")))) | Q43: Нет | R43: Крупный музыкальный уикенд (24–30.08) — пиковая нагрузка на посетительский сервис и парковку. | S43: https://ges-2.org/ges-2-soundsystem-4-body
A44: 43 | B44: ГЭС-2 Саундсистем 4. Spirit* | C44: Лекция | D44: Тяжёлый | E44: 46264 | F44: 46264 | G44: =E44-TODAY() | I44: Продакшн | P44: =IF(COUNTBLANK(J44:O44)=6,"",IF(COUNTIF(J44:O44,"Красный")>0,"Красный",IF(COUNTIF(J44:O44,"Жёлтый")>0,"Жёлтый",IF(COUNTIF(J44:O44,"Не начат")>0,"Не начат","Зелёный")))) | Q44: Нет | R44: Крупный музыкальный уикенд (24–30.08) — пиковая нагрузка на посетительский сервис и парковку. | S44: https://ges-2.org/ges-2-soundsystem-4-spirit
A45: 44 | B45: Песни Палисадника | C45: Лекция | D45: Лёгкий | E45: 46264 | F45: 46264 | G45: =E45-TODAY() | I45: Бронирование площадки и ресурсов | P45: =IF(COUNTBLANK(J45:O45)=6,"",IF(COUNTIF(J45:O45,"Красный")>0,"Красный",IF(COUNTIF(J45:O45,"Жёлтый")>0,"Жёлтый",IF(COUNTIF(J45:O45,"Не начат")>0,"Не начат","Зелёный")))) | Q45: Нет | S45: https://ges-2.org/songs-of-the-front-garden
A46: 45 | B46: Технический сценарий | C46: Прочее | D46: Лёгкий | E46: 46266 | F46: 46366 | G46: =E46-TODAY() | I46: Бронирование площадки и ресурсов | P46: =IF(COUNTBLANK(J46:O46)=6,"",IF(COUNTIF(J46:O46,"Красный")>0,"Красный",IF(COUNTIF(J46:O46,"Жёлтый")>0,"Жёлтый",IF(COUNTIF(J46:O46,"Не начат")>0,"Не начат","Зелёный")))) | Q46: Нет | S46: https://ges-2.org/technical-script
A47: 46 | B47: Вагон пользы и еще тележка | C47: Прочее | D47: Лёгкий | E47: 46269 | F47: 46353 | G47: =E47-TODAY() | I47: Бронирование площадки и ресурсов | P47: =IF(COUNTBLANK(J47:O47)=6,"",IF(COUNTIF(J47:O47,"Красный")>0,"Красный",IF(COUNTIF(J47:O47,"Жёлтый")>0,"Жёлтый",IF(COUNTIF(J47:O47,"Не начат")>0,"Не начат","Зелёный")))) | Q47: Нет | S47: https://ges-2.org/loads-of-benefits-and-a-cartload
A48: 47 | B48: Субботние игры на Платформах | C48: Прочее | D48: Лёгкий | E48: 46270 | F48: 46354 | G48: =E48-TODAY() | I48: Бронирование площадки и ресурсов | P48: =IF(COUNTBLANK(J48:O48)=6,"",IF(COUNTIF(J48:O48,"Красный")>0,"Красный",IF(COUNTIF(J48:O48,"Жёлтый")>0,"Жёлтый",IF(COUNTIF(J48:O48,"Не начат")>0,"Не начат","Зелёный")))) | Q48: Нет | S48: https://ges-2.org/saturday-games
A49: 48 | B49: 1=52 | C49: Прочее | D49: Лёгкий | E49: 46271 | F49: 46292 | G49: =E49-TODAY() | I49: Бронирование площадки и ресурсов | P49: =IF(COUNTBLANK(J49:O49)=6,"",IF(COUNTIF(J49:O49,"Красный")>0,"Красный",IF(COUNTIF(J49:O49,"Жёлтый")>0,"Жёлтый",IF(COUNTIF(J49:O49,"Не начат")>0,"Не начат","Зелёный")))) | Q49: Нет | S49: https://ges-2.org/1-52
A50: 49 | B50: Гала. Пять лет музыки | C50: Концерт | D50: Тяжёлый | E50: 46272 | F50: 46372 | G50: =E50-TODAY() | I50: Продакшн | P50: =IF(COUNTBLANK(J50:O50)=6,"",IF(COUNTIF(J50:O50,"Красный")>0,"Красный",IF(COUNTIF(J50:O50,"Жёлтый")>0,"Жёлтый",IF(COUNTIF(J50:O50,"Не начат")>0,"Не начат","Зелёный")))) | Q50: Нет | S50: https://ges-2.org/projects/gala-five-years-of-music
A51: 50 | B51: Минусболеро | C51: Концерт | D51: Тяжёлый | E51: 46272 | F51: 46272 | G51: =E51-TODAY() | I51: Продакшн | P51: =IF(COUNTBLANK(J51:O51)=6,"",IF(COUNTIF(J51:O51,"Красный")>0,"Красный",IF(COUNTIF(J51:O51,"Жёлтый")>0,"Жёлтый",IF(COUNTIF(J51:O51,"Не начат")>0,"Не начат","Зелёный")))) | Q51: Нет | S51: https://ges-2.org/minusbolero
A52: 51 | B52: Принты и чудики | C52: Прочее | D52: Лёгкий | E52: 46274 | F52: 46288 | G52: =E52-TODAY() | I52: Бронирование площадки и ресурсов | P52: =IF(COUNTBLANK(J52:O52)=6,"",IF(COUNTIF(J52:O52,"Красный")>0,"Красный",IF(COUNTIF(J52:O52,"Жёлтый")>0,"Жёлтый",IF(COUNTIF(J52:O52,"Не начат")>0,"Не начат","Зелёный")))) | Q52: Нет | S52: https://ges-2.org/prints-and-oddballs
A53: 52 | B53: Божественная комедия | C53: Выставка | D53: Тяжёлый | E53: 46275 | F53: 46275 | G53: =E53-TODAY() | I53: Продакшн | P53: =IF(COUNTBLANK(J53:O53)=6,"",IF(COUNTIF(J53:O53,"Красный")>0,"Красный",IF(COUNTIF(J53:O53,"Жёлтый")>0,"Жёлтый",IF(COUNTIF(J53:O53,"Не начат")>0,"Не начат","Зелёный")))) | Q53: Нет | S53: https://ges-2.org/projects/divine-comedy
A54: 53 | B54: Ба-бах! | C54: Прочее | D54: Лёгкий | E54: 46275 | F54: 46338 | G54: =E54-TODAY() | I54: Бронирование площадки и ресурсов | P54: =IF(COUNTBLANK(J54:O54)=6,"",IF(COUNTIF(J54:O54,"Красный")>0,"Красный",IF(COUNTIF(J54:O54,"Жёлтый")>0,"Жёлтый",IF(COUNTIF(J54:O54,"Не начат")>0,"Не начат","Зелёный")))) | Q54: Нет | S54: https://ges-2.org/boom-bach
...

Sheet Этапы по трекам
A1: Трек | B1: Этап | C1: Старт (T-минус, дней) | D1: Дедлайн (T-минус, дней) | E1: Ответственный (R) | F1: Комментарий
A2: Лёгкий | B2: Заявка/утверждение | C2: -45 | D2: -35 | E2: Продюсер | F2: Согласование темы/спикера, бюджет при наличии
A3: Лёгкий | B3: Бронирование площадки и ресурсов | C3: -34 | D3: -21 | E3: Продюсер + Площадка | F3: Аудитория/зал, техника по минимуму
A4: Лёгкий | B4: Маркетинг/PR-план | C4: -20 | D4: -7 | E4: Маркетинг | F4: Анонс в календаре и соцсетях, без спецкампании
A5: Лёгкий | B5: Финальная неделя | C5: -7 | D5: -1 | E5: Продюсер | F5: Финальная сверка тайминга, без брифинга охраны/питания
A6: Лёгкий | B6: Проведение | C6: 0 | D6: 0 | E6: Продюсер | F6: —
A7: Лёгкий | B7: Пост-ивент | C7: 1 | D7: 5 | E7: Продюсер | F7: Короткий отчёт: явка, обратная связь
A8: Средний | B8: Заявка/утверждение | C8: -60 | D8: -45 | E8: Продюсер | F8: Согласование концепции и бюджета
A9: Средний | B9: Бронирование площадки и ресурсов | C9: -44 | D9: -25 | E9: Продюсер + Площадка | F9: Зал/пространство, базовая техника
A10: Средний | B10: Продакшн | C10: -30 | D10: -10 | E10: Продакшн | F10: Монтаж/техническое обеспечение показа или экспозиции
A11: Средний | B11: Маркетинг/PR-план | C11: -30 | D11: -3 | E11: Маркетинг + PR | F11: Анонс, пресс-лист при необходимости
A12: Средний | B12: Финальная неделя | C12: -7 | D12: -1 | E12: Продюсер | F12: Брифинг площадки, проверка готовности зала
A13: Средний | B13: Проведение | C13: 0 | D13: 0 | E13: Продюсер + Площадка | F13: —
... A21: Тяжёлый | B21: Пост-ивент | C21: 1 | D21: 10 | E21: Продюсер | F21: Демонтаж, разбор инцидентов, отчёт по всем метрикам
A23: T-минус — количество дней до даты события (отрицательное = до события, 0 = день события, положительное = после).
A24: Сроки — рабочая гипотеза для старта, требуют сверки с реальными регламентами отделов (не факт ГЭС-2).

Sheet RACI
A1: R — ответственный (делает) · A — согласующий (утверждает) · C — консультируют · I — информируют · пусто — не участвует
A3: Трек: Лёгкий
A4: Этап | B4: Продюсер | C4: Маркетинг | D4: PR | E4: Площадка | F4: Питание | G4: Охрана | H4: Продакшн/техника
A5: Заявка/утверждение | B5: R
A6: Бронирование площадки и ресурсов | B6: A | E6: R
A7: Маркетинг/PR-план | B7: A | C7: R | D7: I
A8: Финальная неделя | B8: R | C8: I | E8: I
A9: Проведение | B9: R | E9: C
A10: Пост-ивент | B10: R | C10: I
A13: Трек: Средний
A14: Этап | B14: Продюсер | C14: Маркетинг | D14: PR | E14: Площадка | F14: Питание | G14: Охрана | H14: Продакшн/техника
A15: Заявка/утверждение | B15: R | C15: C | D15: C | E15: C
A16: Бронирование площадки и ресурсов | B16: A | E16: R | H16: C
A17: Продакшн | B17: A | E17: C | H17: R
A18: Маркетинг/PR-план | B18: A | C18: R | D18: R | E18: I
A19: Финальная неделя | B19: R | C19: I | D19: I | E19: A | F19: I | G19: I | H19: C
A20: Проведение | B20: R | E20: C | H20: C
A21: Пост-ивент | B21: R | C21: C | D21: C | E21: I | H21: I
A24: Трек: Тяжёлый
A25: Этап | B25: Продюсер | C25: Маркетинг | D25: PR | E25: Площадка | F25: Питание | G25: Охрана | H25: Продакшн/техника
A26: Заявка/утверждение | B26: R | C26: C | D26: C | E26: C | F26: C | G26: C | H26: C
A27: Бронирование площадки и ресурсов | B27: A | E27: R | F27: I | G27: I | H27: C
A28: Продакшн | B28: A | E28: C | H28: R
A29: Маркетинг/PR-план | B29: A | C29: R | D29: R | E29: I | H29: I
A30: Финальная неделя | B30: A | C30: I | D30: I | E30: R | F30: R | G30: R | H30: C
A31: Проведение | B31: R | C31: I | D31: I | E31: C | F31: C | G31: C | H31: C
A32: Пост-ивент | B32: R | C32: C | D32: C | E32: C | F32: C | G32: C | H32: C
A35: Состав RACI — стартовая гипотеза, требует проверки с отделами (особенно точки A — кто реально утверждает переход к следующему этапу).

Sheet Дашборд
A1: Дашборд по реестру событий
A2: Считается автоматически из листа 'Реестр событий' (формулы COUNTIF/COUNTIFS).
A4: Всего событий в реестре | B4: =COUNTA('Реестр событий'!B2:B400)
A5: из них уже идут сейчас (статус по датам) | B5: =COUNTIF('Реестр событий'!I2:I400,"Проведение")
A6: из них ещё не начались | B6: =COUNTIFS('Реестр событий'!I2:I400,"<>Проведение",'Реестр событий'!I2:I400,"<>Пост-ивент",'Реестр событий'!B2:B400,"<>")
A8: По трекам
A9: Лёгкий | B9: =COUNTIF('Реестр событий'!D2:D400,"Лёгкий")
A10: Средний | B10: =COUNTIF('Реестр событий'!D2:D400,"Средний")
A11: Тяжёлый | B11: =COUNTIF('Реестр событий'!D2:D400,"Тяжёлый")
A13: По общему статусу (заполняется отделами)
A14: Зелёный | B14: =COUNTIF('Реестр событий'!P2:P400,"Зелёный")
A15: Жёлтый | B15: =COUNTIF('Реестр событий'!P2:P400,"Жёлтый")
A16: Красный | B16: =COUNTIF('Реестр событий'!P2:P400,"Красный")
A17: Не начат | B17: =COUNTIF('Реестр событий'!P2:P400,"Не начат")
A18: Статус ещё не проставлен | B18: =COUNTIFS('Реестр событий'!P2:P400,"",'Реестр событий'!B2:B400,"<>")
A20: Событий с 'Красный' по отделу
A21: Продакшн/техника | B21: =COUNTIF('Реестр событий'!J2:J400,"Красный")
A22: Маркетинг | B22: =COUNTIF('Реестр событий'!K2:K400,"Красный")
A23: PR | B23: =COUNTIF('Реестр событий'!L2:L400,"Красный")
A24: Площадка | B24: =COUNTIF('Реестр событий'!M2:M400,"Красный")
A25: Питание | B25: =COUNTIF('Реестр событий'!N2:N400,"Красный")
A26: Охрана | B26: =COUNTIF('Реестр событий'!O2:O400,"Красный")
A28: В финальной неделе с 'Красный' статусом (нужна эскалация)
A29: Событий | B29: =COUNTIFS('Реестр событий'!I2:I400,"Финальная неделя",'Реестр событий'!P2:P400,"Красный")
A31: Ближайшие крупные операционные точки
A32: Событий с примечанием-предупреждением (столбец 'Риски/комментарий') | B32: =COUNTIF('Реестр событий'!R2:R400,"?*")
